Workbook

Sheet Index
A1: Category | B1: Subsystem / Focus | C1: Sheet Link | D1: Description / Quick Notes
A2: 0.0 Program Control | B2: Mission Overview | C2: M.S. & Objectives | D2: High-level milestones & project goals.
B3: Systems Engineering | C3: Requirements | D3: Master system and subsystem tracking.
A4: 1.0 Payload & Science | B4: Core Instruments | C4: Payload | D4: Breakdown of scientific sensors and components.
A5: 2.0 Operations | B5: Mission Timeline | C5: Outline Key Phases | D5: Chronological breakdown of mission elapsed time.
C6: Concept of Operations Timeline
C7: minute-by-minute breakdown
A8: 3.0 Mechanical & Structure | B8: Mass Tracking | C8: Mass Budget | D8: Margin calculations and weight allocations.
B9: Hardware Trade Studies | C9: Structures Decision Matrix | D9: Comparative analysis of chassis designs.

Sheet M.S. & Objectives
B1: Level | C1: OBJECTIVES & REQUIREMENTS | D1: Objective or Requirement Statement | E1: Date Last Updated | F1: Source(s) | G1: System/ Subsystem(s) Affected? | H1: Status? | I1: CHANGE LOG | J1: Revisions to the Objective/ Requirement | K1: Reasons/ Justification | L1: Source(s) | M1: ASSOCIATED RISKS | N1: Associated Risks with Requirement | O1: VERIFICATION & VALIDATION (V&V) | P1: Testing Method | Q1: Verification Plan | R1: Validation Plan | S1: Any Pre-Actions Needed?
A2: OBJ = Objective, REQ = Requirement, CSR = Constraint. Number Hierarchy = 01.02.03 (01 = Objective Parent Category, 02 = First Child Requirement, 03 = Second Child Requirement... etc) | B2: System, Subsystem, or Component Level? | D2: Full statement sentence. Objectives are the requirements in simple, easy to understand, general terms. Requirements are technical as "shall" statements with a specific, measureable, and testable guideline to be met. | E2: Date of when the requirement statement was last revised. | F2: Where did this requirement come from? Is this based on literature, stakeholder, testing standards, etc? Include links if possible. | G2: Does this matter on a system level? If not, which subsystems does this directly affect? Consider the interfaces as well. Which subsystems are responsible? | H2: Accomplished or unaccomplished? | J2: List by chronological order, with most recent revisions FIRST. Include... (year.month.date) Revision 1 comment, (year.month.date) Revision 2 comment | K2: Why was the revision made? | N2: List the associated risk numbers. | Q2: Verification - Does it meet the specification need? Are we building our product right? | R2: Validation - Does it meet the customer need? Did we build the right product?
A3: MISSION STATEMENT | B3: MISSION STATEMENT | D3: The multi-agent Europa surface system shall autonomously characterize the ice shell and identify a cryobot insertion site, operating without real-time Earth support. | E3: 46187 | F3: - | G3: - | H3: -
A4: OBJ.01 | B4: System Level | D4: The system shall demonstrate autonomous multi-agent coordination and consensus-based decision making without Earth communication links | E4: 46187 | F4: This objective addresses the multi-agent coordination shortfall ranked 139th in NASA's Civil Space Technology Shortfall Rankings, which identifies cooperative task planning as a near-term priority (STMD]
A5: OBJ.02 | B5: Subsystem Mobility | D5: The rover shall traverse Europa's surface terrain and maintain localization using onboard sensors and inter-agent ranging | E5: 46187 | F5: This objective addresses NASA's identified gap in autonomous navigation without Earth-based support, as stated in the FY 2026-2027 SBIR solicitation Topic COMNAV.1.S26B [SBIR]
A6: OBJ.03 | B6: Subsystem Science/Payload | D6: The system shall characterize ice shell thickness using a ground penetrating radar sounder and identify candidate insertion sites | E6: 46187 | F6: This objective supports the science goals outlined in the Decadal Survey, which identifies Europa's subsurface ocean as a primary target for astrobiology and calls for characterization of the ice shell to assess habitability. [OWL]
A7: OBJ.04 | B7: Subsystem COMMs | D7: The inter-agent mesh network shall maintain coordination under degraded connectivity and radiation induced faults | E7: 46187 | F7: This objective addresses NASA's identified gap in autonomous distributed spacecraft operations without Earth-based navigational support, per SBIR Topic COMNAV.1.S26B. [SBIR]

Sheet Requirements
B1: Level | C1: OBJECTIVES & REQUIREMENTS | D1: Objective or Requirement Statement | E1: Date Last Updated | F1: Reasoning | G1: Source(s) | H1: System/ Subsystem(s) Affected? | I1: Status? | J1: CHANGE LOG | K1: Revisions to the Objective/ Requirement | L1: Reasons/ Justification | M1: Source(s) | N1: ASSOCIATED RISKS | O1: Associated Risks with Requirement | P1: VERIFICATION & VALIDATION (V&V) | Q1: Testing Method | R1: Verification Plan | S1: Validation Plan | T1: Any Pre-Actions Needed? | U1: Notes For Final Presentation.
A2: OBJ = Objective, REQ = Requirement, CSR = Constraint. Number Hierarchy = 01.02.03 (01 = Objective Parent Category, 02 = First Child Requirement, 03 = Second Child Requirement... etc) | B2: System, Subsystem, or Component Level? | D2: Full statement sentence. Objectives are the requirements in simple, easy to understand, general terms. Requirements are technical as "shall" statements with a specific, measureable, and testable guideline to be met. | E2: Date of when the requirement statement was last revised. | G2: Where did this requirement come from? Is this based on literature, stakeholder, testing standards, etc? Include links if possible. | H2: Does this matter on a system level? If not, which subsystems does this directly affect? Consider the interfaces as well. Which subsystems are responsible? | I2: Accomplished or unaccomplished? | K2: List by chronological order, with most recent revisions FIRST. Include... (year.month.date) Revision 1 comment, (year.month.date) Revision 2 comment | L2: Why was the revision made? | O2: List the associated risk numbers. | R2: Verification - Does it meet the specification need? Are we building our product right? | S2: Validation - Does it meet the customer need? Did we build the right product? | U2: What work did you do for this requirement this semester
A3: REQ.01.01 | B3: System [Mission level] | D3: The multi-agent Europa system shall operate fully autonomously for the entire surface mission duration without requiring real-time command uplinks from Earth. | E3: 46187 | F3: The 44-minute one-way light delay between Earth and Jupiter makes real-time demanding physically impossible, all decisions must be onboard. Traceable to OBJ.01 | G3: NASA FY 2026-2027 SBIR Solicitation, Topic COMNAV.1.S26B, 2025 | H3: System | I3: Unaccomplished | O3: Risk-01: Single-point autonomy failure with no fallback human override | Q3: Hardware-in-the-loop simulation. Run a 72-hour autonomous mission sequence with a simulated 44-min communication blackout, and verify zero unresolved command dependencies on Earth. | R3: Verify the software autonomously executes all planned traverses, consensus rounds, and science data collected without any Earth uplink during the blackout window. | S3: Demonstrate that the mission objectives are achieved across three independent HILL runs without Earth support
A4: REQ.01.02 | B4: System [Mission level] | D4: The system shall survive and maintain operational status after exposure to total ionizing dose of no less than 100 krad over the nominal mission lifetime. | E4: 46187 | F4: Jupiter's magnetosphere delivers radiation doses far exceeding near-Earth missions. Europas Clipper's radiation vault architecture targets ~100 krad as the design threshold. Radiation environment directly drives the shielded vault requirement. Traceable to OBJ.01 | G4: National Academies, Origins Worlds and Life Decadal Survey 2023–2032, https://www.nationalacademies.org/read/26522; Galileo spacecraft radiation vault design heritage | H4: System, Electronics, Power | I4: Unaccomplished | O4: RISK-02: Accumulated single event upsets degrade consensus algorithm convergence before mission completion. | Q4: Co-60 gamma irradiation of all radiation-sensitive components to 110 krad (10% margin). Monitor functional performance throughout exposure. | R4: Verify all components pass functional tests at end of life dose with no loss of required functionality | S4: Validate the integrated rover and relay nodes complete simulated mission operations after TID exposure.
A5: REQ.01.03 | B5: System [Mission level] | D5: The system shall maintain a minimum inter-agent network connectivity of two active relay nodes at all times during surface operations to ensure consensus is achievable. | E5: 46187 | F5: Consensus algorithms require a minimum connected graph to guarantee convergence. Two active relays plus a surface rover guarantee a 3-node connected topology as the minimum viable configuration. Traceable to OBJ.01 and OBJ.04. | G5: NASA STMD Civil Space Technology Shortfall Rankings, Jul. 2024, https://www.nasa.gov/wp-content/uploads/2024/07/civil-space-shortfall-ranking-july-2024.pdf | H5: System, COMMs | I5: Unaccomplished | O5: RISK-03: Simultaneous radiation-induced failure of multiple relay nodes isolating the surface rover. | Q5: Network fault simulation: simulate progressive relay node failures and verify consensus detects degenerated topology and triggers reconfiguration before dropping below 2 active nodes. | R5: Verify that fault detection and reconfiguration logic activates within one consensus cycle period upon detection of a node loss event. | S5: Validate that the surface rover completes a traverse plan using map data from a degraded 2-relay configuration.
A6: REQ.02.01 | B6: Subsystem [Operations Level] Mobility | D6: The surface robot shall maintain a localization accuracy of no worse than +-0.5 m relative to its last known position during any traverse segments up to 50 m in the absence of GPS. | E6: 46187 | F6: Cryobot insertion site selection requires meter-level positioning to match the radar identified thin ice candidate. +-0.5 over 59 m segments in consistent with visual odometry performance on Mars rovers. Traceable to OBJ.02 | G6: NASA FY 2026-2027 SBIR Solicitation, Topic COMNAV.1.S26B; Mars Curiosity rover visual odometry heritage | H6: Mobility, GNC | I6: Unaccomplished | O6: RISK-04: Ice surface texture homogeneity reducing visual odometry feature tracking quality. | Q6: Field test on analog terrain: command 50m traverse segments and compare onboard state estimate to ground truth GPSD position across 20 runs under varying terrain conditions. | R6: verify that position error remains within +-0.5 m across a minimum of 20 traverse segments. | S6: Validate that the rover navigates to and stops within +-0.5 m of a designated waypoint representing a candidate insertion site.
A7: REQ.03.01 | B7: Subsystem [Operations Level] Science / Payload | D7: The ground-penetrating radar sounder shall resolve ice shell thickness to within +-10% accuracy for ice layers between 1 km and 30 km depth, producing a subsurface map at the minimum spatial resolution of 100 m along the traverse track. | E7: 46187 | F7: Identifying optimal cryobot insertion site requires knowing where the ice shell is the thinnest. +- 10% thickness accuracy is enough to distinguish viable drilling candidates. The 100 m along track resolution is consistent with the Europa Clipper REASON instrument design parameters. Traceable to OBJ.03 | G7: National Academies, Origins Worlds and Life Decadal Survey 2023–2032, https://www.nationalacademies.org/read/26522; Europa Clipper REASON instrument documentation | H7: Science/Payload, Power | I7: Unaccomplished | O7: RISK-05: Ice shell heterogeneity or brine inclusions creating radar clutter that degrades thickness estimates. | Q7: Laboratory radar range measurements against ice targets of known thickness using dielectric matches analogs, verify +- 10% accuracy across the 1-30 km depth range. | R7: Verify that the radar sounder produces subsurface profiles with +-10% depth accuracy against calibration targets before rover integration. | S7: Validate that the subsurface map produces during a field traverse correctly identifies presurveyed thin ice candidate sites within the required spatial resolution.
A8: REQ.04.01 | B8: Subsystems [Operations Level] COMMS | D8: The inter-agent mesh network shall achieve consensus on a shared consensus on a shared terrain map update within no more than 10 minutes under a degraded network condition defined as packet loss rates of up to 30% on any single inter-agent link | E8: 46187 | F8: Rover traverse planning depends on a current consensus validated terrain map. A 10 minute convergence bound limits traverse planning delay to an acceptable operations cadence. 30% packet loss represents a plausible radiation induced degradation scenario for the environment. Traceable to OBJ.04. | G8: NASA STMD Civil Space Technology Shortfall Rankings, Jul. 2024; NASA FY 2026-2027 SBIR Solicitation, Topic COMNAV.1.S26B | H8: COMMs, CDH | I8: Unaccomplished | O8: RISK-06: Radiation induced burst errors exceeding 30% packet loss on multiple links simultaneously, stalling consensus. | Q8: Software-in-the-loop consensus simulation: Introduce 30% packet loss on each inter-agent link and measure convergence time across 100 test runs. | R8: Verify the consensus convergence time remains <10 minutes across all 100 test runs with 30% packet loss. | S8: Validate that the rover initiates a traverse using a map update produced by the consensus protocol under the degraded link test condition.
A9: REQ.03.02 | B9: Subsystem [Operation Level} Science / payload | D9: The radar sounder antenna shall be mounted such that the antenna boresight remains within +-5 of nadir during all active sounding operations; the rover shall halt traversal if the measured surface slope exceeds 20 to maintain pointing compliance. | E9: 46189 | F9: A nadir pointing antenna is required to minimize geometric error in the two-way travel time measurement. . Off nadir tilt reduces basal reflection return strength and introduces range error that degrades | G9: National Academies, Origins Worlds and Life Decadal Survey 2023–2032; Europa Clipper REASON instrument documentation | H9: Science/Payload, Structures, Mobility | I9: Unaccomplished | O9: RISK-05: Ice shell heterogeneity creating radar clutter that degrades thickness estimates; RISK-04: Ice surface texture reducing visual odometry quality (slope-stop logic dependency) | Q9: Bench test antenna mounting fixture: tilt rover chassis to 5° increments and measure antenna boresight deviation using an inclinometer. Verify pointing error stays within ±5° across the full range of surface slopes up to 20°. | R9: Verify that antenna boresight deviation does not exceed ±5° of nadir across all chassis tilt angles up to 20° slope | S9: Validate that the rover correctly halts traversal and resumes sounding when slope threshold is exceeded during an analog terrain field test.
A10: REQ.03.03 | B10: Subsystem [Operations Level] Science / Payload | D10: The rover power subsystem shall reserve a dedicated peak power allocation for radar sounder transmission pulses and shall command drive motor shutdown during each active sounding window to prevent power contention with the RTG continuous output. | E10: 46189 | F10: Radar sounders draw high peak pulse power during transmission. The RTG provides fixed continuous output; simultaneous drive and sounding would exceed available power margin and risk under-powering the radar pulse, degrading return signal amplitude below the noise floor. Stop-and-sound is consistent with high-power instrument operation heritage on Mars rovers. Traceable to OBJ.03. | G10: Europa Clipper REASON instrument documentation; NASA RTG power system heritage | H10: Science/Payload, Power, Mobility | I10: Unaccomplished | O10: RISK-02: Accumulated single event upsets degrade system performance; RISK-05: Degraded radar return amplitude from insufficient transmission power | Q10: Hardware-in-the-loop power budget simulation: command simultaneous drive and sounding operations and monitor RTG output margin across 50 test cycles. Verify drive shutdown command fires before each sounding pulse. | R10: Verify that drive motors are commanded off prior to every sounding transmission and that RTG output margin remains positive across all test cycles. | S10: Validate that the rover completes a full simulated traverse sol with correct stop-and-sound behavior and no power fault events.
A11: REQ.03.04 | B11: Subsystem [Operations Level] Science / Payload | D11: The command and data handling subsystem shall provide onboard storage sufficient to retain a minimum of 7 sols of uncompressed radar trace data, and shall apply lossless compression to all Radar_Traces records prior to inter-agent relay transmission, achieving a minimum compression ratio of 2:1. | E11: 46189 | F11: At approximately 40 traces per sol across four data sheets, raw science data accumulates faster than the non-deterministic Earth relay can downlink. Seven sols of buffer covers the consensus convergence window and plausible communication gaps. Lossless compression preserves the measurement fidelity required by REQ.03.01 while reducing relay load. Traceable to OBJ.03 and OBJ.04. | G11: NASA STMD Civil Space Technology Shortfall Rankings, Jul. 2024; Europa Clipper REASON instrument documentation | H11: Science/Payload, COMMs, CDH | I11: Unaccomplished | O11: RISK-06: Radiation induced burst errors exceeding 30% packet loss stalling consensus; RISK-05: Ice shell heterogeneity generating excess CLUTTER traces inflating data volume | Q11: Software-in-the-loop storage simulation: generate 7 sols of synthetic radar trace data at full volume and verify onboard storage does not overflow. Apply compression algorithm and measure output ratio across 100 data sets. | R11: Verify that onboard storage accommodates 7 sols of uncompressed data and that compression ratio meets or exceeds 2:1 across all 100 test data sets. | S11: Validate that compressed science data downlinked through the inter-agent mesh under 30% packet loss conditions can be fully reconstructed without data loss on the receiving node.
A12: REQ.05.01 | B12: Subsystem [Operational Level] Thermal | D12: The rover thermal control system shall maintain all avionics and battery cells within an operational temperature range of 0C to 40C during all active surface operations and above -20C during night-mode low-power thermal management, using active heater elements powered by RTG waste heat. | E12: 46201 | F12: Europa's surface temperature is approximately 90K (-183C). Battery cells experience severe capacity loss below -20C and permanent damage below -40C. The RTG provides continuous waste heat that can be routed to a thermal enclosure, making active heating feasible without a dedicated power draw penalty. No ground intervention is possible to recover a thermally failed rover. Traceable to OBJ.01. | G12: National Academies, Origins Worlds and Life Decadal Survey 2023–2032; NASA RTG thermal heritage | H12: Thermal, Power, Structures | I12: Unaccomplished | O12: RISK-07: Thermal control failure during extended night-mode causing battery cell damage and mission termination | Q12: Thermal-Vacuum chamber test: Subject the integrated rover to Europa analog thermal cycling (90K surface, simulated RTG waste heat input) and monitor avionics and battery temperatures across a full 23 hour sol cycle including night-mode. | R12: Verify that avionics and battery temperatures remain within required bounds across three consecutive sol cycles in the thermal vacuum chamber with no active ground commands. | S12: Validate that the rover completes a simulated surface traverse sol following a full night-mode thermal cycle without any subsystem degradation or heater fault events.
A13: REQ.05.02 | B13: Subsystem [Operations Level] CDH | D13: The command and data handling subsystem shall detect and autonomously recover from a single-event latchup in any processor core within 330 seconds of occurrence, restoring nominal operations without ground intervention, and shall log each latchup event to non-volatile memory with a timestamp and affected core identifier. | E13: 46201 | F13: Jupiter's magnetosphere produces a high-energy particle flux that induces single event latchup at a far higher rate than near-Earth missions. With a 44-minute one-way light delay, no ground intervention can recover a locked core in time to prevent missions tall. The 30-second recovery bound prevents autonomous traverse planning and site selection from stalling indefinitely. Traceable to OBJ.01, linked to RISK-02. | G13: National Academies, Origins Worlds and Life Decadal Survey 2023–2032; NASA STMD Civil Space Technology Shortfall Rankings, Jul. 2024; Galileo spacecraft radiation heritage | H13: CDH, Electronics | I13: Unaccomplished | O13: RISK-02: Accumulated single event upsets degrade consensus algorithm convergence before mission completion. | Q13: Hardware-in-the-loop fault injection: Inject simulated single-event latchup signals into each processor core and measure time from latchup detection to nominal operation restoration across 50 test runs per core. | R13: Verify that the recovery from the latchup injection occurs within 30 seconds across all 50 test runs for each core, and that each event is correctly logged to non-volatile memory with timestamp and code ID. | S13: Validate that the rover autonomously continues a planned traverse sequence without human intervention following a lachup event injected mid-traverse during an analog mission simulation.
A14: REQ.05.03 | B14: Subsystem [Operations Level] Power | D14: The rover power management subsystem shall enforce a per-sol energy budget such that total energy draw across all subsystems does not exceed 90% of the RTG's nominal daily energy output, reserving a minimum 10% margin for autonomous anomaly response, heater activations, and unplanned communication relay passes. | E14: 46201 | F14: The RTG provides fixed continuous output with no ability to surge on demand. Radiation-induced matchups, slope-stop halts per REQ.03.02, and degraded consensus requiring extra relay passes all introduce unscheduled power draws. A hard 10% reserve prevents the rover from entering a power fault state during autonomous recovery events with no ground support available. Traceable to OBJ.01 and OBJ.03 | G14: NASA RTG power system heritage; Europa Clipper power budget architecture; NASA FY 2026–2027 SBIR Solicitation, Topic COMNAV.1.S26B | H14: Power, CDH, Thermal, Mobility | I14: Unaccomplished | O14: RISK-02: Accumulated single event upsets degrade consensus algorithm convergence before mission completion. RISK-07: Thermal control failure during extended night-mode causing battery cell damage and mission termination | Q14: Hardware-in-the-Loop power budget simulation: Run a full synthetic sol sequence with simultaneous drive, sounding, heating, and consensus relay operations and monitor RTG output margin continuously across 550 test cycles, including injected anomaly events. | R14: Verify that the total per-sol energy draw does not exceed 90% of RTG nominal output across all 50 test cycles, including cycles with injected anomaly events that trigger unschedules heater and relay draws. | S14: Validate that the rover completes a full simulated traverse sol with one injected latch up and one slope-stop event without triggering a power fault or dropping below that 10% reserve margin.
... A29: REQ.10.03 | B29: Subsystem [Design] COMMs | D29: The rover-to-relay proximity link shall close with no less than 3 dB of margin over the Eb/N0 required for a post-decoding bit error rate of 1E-6 at the worst-case 588 km slant range in both directions, and the rover shall retain an X-band direct-to-Earth engineering beacon of no less than 5 bps to a DSN 34 m station as a relay-loss fallback. | E29: 46231 | F29: 3 dB is the standard allowance for a proximity link whose orbit geometry, antenna pattern, and receiver noise floor are only coarsely known before flight, and at UHF the Jovian synchrotron contribution to system noise temperature is the hardest term to bound from the ground. A 1E-6 coded error rate keeps frame loss inside what the consensus protocol already tolerates at 30% packet loss (REQ.04.01). The beacon exists because the link budget shows a direct X-band link on an LGA closes at only ~7 bps at 4.2 AU, enough to report state but nowhere near enough to run the mission. That number is what makes the relay architecture non-optional rather than convenient. | G29: Link budget analysis (3.5); JPL DSN Telecommunications Link Design Handbook 810-005; CCSDS 131.0-B turbo/LDPC coding performance; JPL Electra-Lite UHF transceiver specification; REQ.04.01 degraded-mode consensus | H29: COMMs, Power, Structures, CDH | I29: Unaccomplished | O29: RISK-18: Jovian synchrotron noise at UHF raising relay receiver system noise temperature above the assumed 3000 K and eroding return-link margin | Q29: Radiated compatibility test in an anechoic chamber with the flight helix on a rover mock-up, plus a bit error rate sweep against an injected noise floor scaled to the assumed system noise temperature. | R29: Verify measured Eb/N0 at the worst-case 588 km slant range exceeds the coded 1E-6 threshold by no less than 3 dB in both directions, and that the X-band chain closes a 5 bps beacon at 4.2 AU. | S29: Validate that the rover autonomously falls back to the X-band beacon and continues safe-mode operations when both relay links are withheld for a full simulated sol.

Sheet Payload
A1: Timestamp_UTC | B1: Sol | C1: Pressure_mbar | D1: AirTemp_C | E1: GroundTemp_C | F1: Humidity_pct | G1: WindSpeed_mps | H1: WindDir_deg | I1: Dust_OpticalDepth | J1: Radiation_Wm2 | K1: Data_Quality_Flag

Sheet Outline Key Phases of the Missi
A1: Time (UTC or Mission Elapsed Time) | B1: Robot Function / Mode | C1: Primary Objective / Milestone | D1: Operation Mode (Teleop / Autonomous / Semi-Autonomous / Scripted) | E1: Inputs (e.g., command, signal, state) | F1: Expected Outputs (e.g., telemetry, sensor data) | G1: Data Products Generated | H1: Verification Method | I1: Associated Risk or Sensitivity (High/Med/Low) | J1: Dependencies / Predecessor Actions | K1: Estimated Duration | L1: Notes
A2: Launch day, 0-1 (Mission Elapsed Time) | B2: Launch And Commissioning | C2: Spacecraft Separation and initial health checks | D2: Scripted/Autonomous | E2: Launch vehicle separation signal, onboard startup sequences | F2: Spacecraft status telemetry, power system telemetry, communication link confirmation | G2: Initial spacecraft health report, subsystem status logs | H2: Verify successful separation communication establishment, and nominal subsystem health/ | I2: High | J2: Successful vehicle loading and spacecraft deployment | K2: 1 day
A3: Cruise Phase, Years 0-6 | B3: Cruise And Approach | C3: Maintain spacecraft health and perform trajectory correction maneuvers | D3: Semi-Autonomous | E3: Ground-planned trajectory updates, star tracker measurements, navigation state estimates | F3: Navigation telemetry, spacecraft health telemetry, maneuver confirmation | G3: Trajectory correction logs, navigation solution history | H3: Verify trajectory remains within mission tolerance and all spacecraft systems remain operational | I3: Medium | J3: Completion of launch and commision phase | K3: ~6 years
A4: Europa Orbital Insertion and Reconnaissance | B4: Europa Orbit Insertion And Orbital Reconnaissance | C4: Deploy orbital agents and identify suitable landing region | D4: Autonomous | E4: Orbital state estimates, terrain imaging data, radar survey measurements | F4: Surface maps, hazard maps, candidate landing sites | G4: Global terrain map, landing site assessment report | H4: Verify successful orbital insertion, orbiter deployment, and identification of viable landing zones. | I4: High | J4: Successful arrival at Europa and orbital insertion burn | K4: 30 Days
A5: Surface Operations Day 0-5 | B5: Landing, Surface Checkout, And Site Characterization | C5: Deploy rover, verify system health, and calibrate science instruments. | D5: Autonomous | E5: Landing state, rover deployment commands, sensor calibration routines | F5: Health telemetry, localization estimates, calibration measurements | G5: System checkout report, calibration datasets, local terrain map | H5: Verify successful rover deployment, communications, localization accuracy, and payload calibration | I5: High | J5: Reconnaissance complete and landing site selected | K5: 5 Days
A6: Surface Operations Day 5-35 | B6: Surface Survey And Ice Characterization | C6: Map subsurface ice structure and identify candidate cryobot insertion sites | D6: Autonomous | E6: Ground-penetrating radar returns, orbital terrain map, localization state estimations | F6: Ice thickness estimates, terrain classifications, rover position estimates | G6: Subsurface radar maps, ice thickness profiles, candidate cryobot site database, consensus terrain maps | H6: Verify radar measurements meet required accuracy and candidate sites satisfy mission selection criteria | I6: Medium | J6: Successful rover deployment and payload calibration | K6: 30 Days
A7: Surface Operations Day 35-50 | B7: Data Transmission And End Of Mission | C7: Downlink mission data, select final cryobot site, and safely passivate system | D7: Semi-Autonomous | E7: Stored science data, final site selection results, mission completion commands | F7: Mission archive transmission, final health telemetry, passivation confirmation | G7: Final mission report, validated cryobot insertion site package, complete science archive | H7: Verify all science data successfully transmitted and spacecraft enters safe passivated state | I7: Low | J7: Completion of science objectives and final site selection | K7: 15 days

Sheet ImplementationStatus
A1: Level | B1: Requirement No. | C1: Source | D1: Requirement | E1: Implementation | F1: Validation Before TVC | G1: Status (MET/ WIP/ UNMET) | H1: Date Last Updated | I1: Instructions (do not copy this column)
A2: =Requirements!B3 -> System [Mission level] | B2: =Requirements!A3 -> REQ.01.01 | I2: Do not edit Columns A - C. To update them, use the "Requirements" sheet.
A3: =Requirements!B12 -> Subsystem [Operational Level] Thermal | B3: =Requirements!A12 -> REQ.05.01 | I3: In Column A, look for your subsystem's requirements.
A4: =#REF! -> #REF! | B4: =#REF! -> #REF! | I4: In Column D, state how you are implementing design / assembly / integration / testing plans to meet the requirement.
A5: =#REF! -> #REF! | B5: =#REF! -> #REF! | I5: In Column E, state the status - if the Requirement is Met, Unmet, or a Work in Progress (WIP) based on the Implementation description.
A6: =Requirements!B13 -> Subsystem [Operations Level] CDH | B6: =Requirements!A13 -> REQ.05.02 | I6: Be sure to state in Column F if the Implementation/Status has been updated.
A7: =Requirements!B14 -> Subsystem [Operations Level] Power | B7: =Requirements!A14 -> REQ.05.03
A8: =#REF! -> #REF! | B8: =#REF! -> #REF!
A9: =#REF! -> #REF! | B9: =#REF! -> #REF!
A10: =Requirements!B15 -> Subsystem [Operation Level] Mobility | B10: =Requirements!A15 -> REQ.06.01
A11: =Requirements!B16 -> Subsystem [Operations Level] Science / Payload | B11: =Requirements!A16 -> REQ.06.02
A12: =Requirements!B17 -> Subsystem [Operations Level] COMMs | B12: =Requirements!A17 -> REQ.06.03
A13: =Requirements!B30 | B13: =Requirements!A30
A14: =#REF! -> #REF! | B14: =#REF! -> #REF!
A15: =#REF! -> #REF! | B15: =#REF! -> #REF!
A16: =#REF! -> #REF! | B16: =#REF! -> #REF!
A17: =#REF! -> #REF! | B17: =#REF! -> #REF!
A18: =#REF! -> #REF! | B18: =#REF! -> #REF!
A19: =#REF! -> #REF! | B19: =#REF! -> #REF!
A20: =#REF! -> #REF! | B20: =#REF! -> #REF!
A21: =#REF! -> #REF! | B21: =#REF! -> #REF!
A22: =#REF! -> #REF! | B22: =#REF! -> #REF!
A23: =#REF! -> #REF! | B23: =#REF! -> #REF!
A24: =#REF! -> #REF! | B24: =#REF! -> #REF!
A25: =#REF! -> #REF! | B25: =#REF! -> #REF!
... A39: =#REF! -> #REF! | B39: =#REF! -> #REF!

Sheet Concept of Operations Timeline
A1: Time (UTC or Mission Elapsed Time) | B1: Robot Function / Mode | C1: Primary Objective / Milestone | D1: Operation Mode (Teleop / Autonomous / Semi-Autonomous / Scripted) | E1: Inputs (e.g., command, signal, state) | F1: Expected Outputs (e.g., telemetry, sensor data) | G1: Data Products Generated | H1: Verification Method | I1: Associated Risk or Sensitivity (High/Med/Low) | J1: Dependencies / Predecessor Actions | K1: Estimated Duration | L1: Notes
A2: Launch Day | B2: Launch & Commission | C2: Deploy Spacecraft And Establish Communications | D2: Scripted/Autonomous | E2: Launch separation signal, startup sequences | F2: Telemetry, power status, comm link | G2: Initial health report | H2: Verify separation and subsystem health | I2: High | J2: Launch vehicle deployment | K2: 1 day | L2: Mission Start
A3: Cruise Years 1-6 | B3: Cruise & Approach | C3: Transit To Europa | D3: Semi-Autonomous | E3: Navigation measurements, trajectory updates | F3: Navigation telemetry | G3: Trajectory correction logs | H3: Verify trajectory tolerance | I3: Medium | J3: Launch Complete | K3: 6 years | L3: Periodic health monitoring
A4: Europa Arrival | B4: Europa Orbit Insertion | C4: Achieve Stable Europa Orbit | D4: Autonomous | E4: Orbital state measurements | F4: Orbital telemetry | G4: Orbit determination solution | H4: Verify stable orbit | I4: High | J4: Cruise Complete | K4: 1 day | L4: Critical maneuver
A5: Orbit Day 1-15 | B5: Terrain Mapping | C5: Generate Landing Candidates | D5: Autonomous | E5: Orbital imagery, radar scans | F5: Hazard maps | G5: Global terrain maps | H5: Verify terrain coverage | I5: Medium | J5: Orbit Insertion complete | K5: 15 das | L5: Orbital Agent 1
A6: Orbit Day 15-30 | B6: Communications Relay & Localization Support | C6: Validate Landing Regions | D6: Autonomous | E6: Orbital navigation data | F6: Localization updates | G6: Navigation support database | H6: Verify location accuracy | I6: Medium | J6: Terrain Mapping complete | K6: 15 days | L6: Orbital Agent 2
A7: Surface Day 0 | B7: Rover Landing | C7: Safe Landing | D7: Autonomous | E7: Landing guidance sensors | F7: Landing telemetry | G7: Landing performance report | H7: Verify touchdown location | I7: High | J7: Landing Site selected | K7: 4 hrs | L7: Highest risk phase
A8: Surface Day 1 | B8: Payload Initialization | C8: Activate Science Payloads | D8: Autonomous | E8: Startup commands | F8: Instrument health telemetry | G8: Payload status report | H8: Verify payload functionality | I8: Medium | J8: Landing Complete | K8: 6 hrs | L8: New 2.4 activity
A9: Surface Day 1-2 | B9: Radar Calibration | C9: Calibrate Radar Sonar | D9: Autonomous | E9: Calibration routines | F9: Calibration measurements | G9: Calibration dataset | H9: Verify measurement accuracy | I9: Low | J9: Payload initialization complete | K9: 1 day | L9: New 2.4 activity
A10: Surface Day 2-5 | B10: Traverse Planning | C10: Generate Survey Route | D10: Autonomous | E10: Terrain maps, hazard maps | F10: Planned route | G10: Navigation plan | H10: Verify route safety | I10: Medium | J10: Calibration complete | K10: 3 days | L10: New 2.4 activity
A11: Surface Day 5-20 | B11: Autonomous Navigation | C11: Transverse Survey Area | D11: Autonomous | E11: Terrain maps, localization estimates | F11: Position updates | G11: Traverse logs | H11: Verify localization accuracy | I11: Medium | J11: Route planning complete | K11: 15 days | L11: Expanded from 2.3
A12: Surface Day 5-20 | B12: Radar Data Collected | C12: Acquire Subsurface Measurements | D12: Autonomous | E12: Radar returns | F12: Ice thickness estimates | G12: Radar profiles | H12: Verify coverage requirements | I12: Medium | J12: Navigation Active | K12: 15 days | L12: Expanded from 2.3
... A16: Surface Day 29-30 | B16: Data transmission & End Mission | C16: Downlink Archive And Close Mission | D16: Semi-Autonomous | E16: Science archive | F16: Archive transmission | G16: Final mission report | H16: Verify archive receipt | I16: Low | J16: Site selection complete | K16: 1 day | L16: Mission end

Sheet minute-by-minute breakdown
A1: Sol | B1: Mission Elapsed Time (min) | C1: Mode: Sub-Activity | E1: Minute By Minute Ranges
A2: 0 | B2: 0-15 | C2: Europa Descent And Landing | E2: Mode | F2: Duration (min)
A3: 0 | B3: 16-30 | C3: Verify Successful Landing | E3: Initialization
A4: 0 | B4: 31-120 | C4: Rover Commissioning And Health Checks | E4: Europa Descent And Landing | F4: 15
A5: 0 | B5: 121-180 | C5: Orbital Communications Verification | E5: Verify Successful Landing | F5: 15
A6: 0 | B6: 181-300 | C6: Localization Initialization | E6: Rover Commissioning And Health Checks | F6: 90
A7: 0 | B7: 301-420 | C7: Radar Payload Initialization | E7: Orbital Communications Verification | F7: 60
A8: 0 | B8: 421-540 | C8: Radar Calibration And Validation | E8: Localization Initialization | F8: 120
A9: 0 | B9: 541-720 | C9: Initial Site Characterization | E9: Radar Payload Initialization | F9: 120
A10: 0 | B10: 721-1440 | C10: Night Low-Power Thermal Management | E10: Radar Calibration And Validation | F10: 120
A11: 1 | B11: 1441-1500 | C11: Autonomous Traverse Plan | E11: Initial Site Characterization | F11: 180
A12: 1 | B12: 1501-1560 | C12: Orbital Terrain Mapping Update | E12: Night Low-Power Thermal Management | F12: 720
A13: 1 | B13: 1561-1800 | C13: Surface Survey Block A | E13: Activation State
A14: 1 | B14: 1801-1860 | C14: Localization Verification | E14: Autonomous Traverse Plan | F14: 60
A15: 1 | B15: 1861-2100 | C15: Radar Data Collection Block A | E15: Orbital Terrain Mapping Update | F15: 60
A16: 1 | B16: 2101-2190 | C16: Communication Relay Pass | E16: Surface Survey Block A | F16: 240
A17: 1 | B17: 2191-2400 | C17: Surface Survey Block B | E17: Localization Verification | F17: 60
A18: 1 | B18: 2401-2880 | C18: Night Low-Power Thermal Management | E18: Radar Data Collection Block A | F18: 240
A19: 2 | B19: 2881-2940 | C19: Systems Warm-Up | E19: Communication Relay Pass | F19: 90
A20: 2 | B20: 2941-3240 | C20: Radar Data Collection Block B | E20: Surface Survey Block B | F20: 210
A21: 2 | B21: 3241-3300 | C21: Autonomous Hazard Assertion Plan | E21: Systems Warm-Up | F21: 60
A22: 2 | B22: 3301-3540 | C22: Surface Survey Block C | E22: Radar Data Collection Block B | F22: 300
A23: 2 | B23: 3541-3630 | C23: Communication Relay Pass | E23: Autonomous Hazard Assertion Plan | F23: 60
A24: 2 | B24: 3631-3900 | C24: Subsurface Ice Map Generation | E24: Surface Survey Block C | F24: 240
A25: 2 | B25: 3900-4320 | C25: Night Low-Power Thermal Management | E25: Communication Relay Pass | F25: 90
A26: STEADY STATE OPERATIONS | E26: Subsurface Ice Map Generation | F26: 270
A27: 46106 | B27: Repeating Daily Cycle | C27: Traverse Planning | E27: Steady State
A28: 46106 | B28: Repeating Daily Cycle | C28: Survey Operations | E28: Traverse Planning | F28: 60
A29: 46106 | B29: Repeating Daily Cycle | C29: Radar Data Collection | E29: Survey Operations | F29: 240
A30: 46106 | B30: Repeating Daily Cycle | C30: Communications Relay Pass | E30: Radar Data Collection | F30: 300
A31: 46106 | B31: Repeating Daily Cycle | C31: Subsurface Ice Map Updates | E31: Communications Relay Pass | F31: 90
A32: 46106 | B32: Repeating Daily Cycle | C32: Night Low-Power Thermal Management | E32: Subsurface Ice Map Updates | F32: 270
A33: SITE SELECTION PHASE | E33: Autonomous Consensus Validation | F33: 120
A34: 26 | B34: 36001-36360 | C34: Candidate Site Ranking | E34: Candidate Site Ranking | F34: 120
A35: 26 | B35: 36361-36720 | C35: Autonomous Consensus Validation | E35: Night Low-Power Thermal Management | F35: 240
A36: 26 | B36: 36721-37440 | C36: Night Low-Power Thermal Management | E36: SITE SELECTION PHASE
A37: 27 | B37: 37441-37800 | C37: Candidate Site Ranking | E37: Candidate Site Ranking | F37: 360
A38: 27 | B38: 37801-38160 | C38: Autonomous Consensus Validation | E38: Autonomous Consensus Validation | F38: 360
A39: 27 | B39: 38161-38880 | C39: Night Low-Power Thermal Management | E39: Final Site Assessment | F39: 360
A40: 28 | B40: 38881-39240 | C40: Final Site Assessment | E40: Cryobot Site Selection | F40: 360
...

Sheet Mass Budget
A1: Subsystem | B1: Component | C1: Qty. | D1: Mass (kg) | E1: Notes and Rational | G1: Subsystem | H1: Total Mass (kg) | I1: % Dry Mass
A2: Structure | B2: Primary equipment decks/plates | C2: 2 | D2: 5.24 | E2: Parametric sizing for rover avionics and GPR antenna footprints | G2: Structure | H2: =SUM(D2:D10) -> 25.75 | I2: =(H2/$D$27)*100 -> 21.859083
A3: Structure | B3: Landing Legs (struts and footpads) | C3: 4 | D3: 10.36 | E3: 2.59 kg/leg sized to tolerate <12g vertical, 6g lateral touchdown loads | G3: Thermal | H3: =SUM(D11:D14) -> 18.86 | I3: =(H3/$D$27)*100 -> 16.010187
A4: Structure | B4: Stiffener/ brackets/ frames | C4: 1 | D4: 1.88 | E4: ~0.515 kg each; prevent deck deflection under landing loads | G4: Power | H4: =SUM(D15:D18) -> 54.74 | I4: =(H4/$D$27)*100 -> 46.468591
A5: Structure | B5: Fasteners and support hardware | C5: 1 | D5: 1.42 | E5: integration allowance ~q.5-2% of structural mass; cryogenic-rated titanium M5/M6 | G5: Comms | H5: =SUM(D19:D21) -> 5.71 | I5: =(H5/$D$27)*100 -> 4.8471986
A6: Structure | B6: Fastener contingency reserve | C6: 1 | D6: 0.73 | E6: 5% structural mass contingency; spare fasteners / integration allowance | G6: Avionics/OBC | H6: =SUM(D22:D23) -> 4.06 | I6: =(H6/$D$27)*100 -> 3.4465195
A7: Structure | B7: Antenna mast & mounting bracket | C7: 1 | D7: 2.14 | E7: GPR antenna pedestal, Al tube + SS fasteners + thermal isolators for nadir pointing | G7: Payload | H7: =D24 -> 5.5 | I7: =(H7/$D$27)*100 -> 4.6689304
A8: Structure | B8: Radiation shielding vault enclosure | C8: 2 | D8: 2.08 | E8: Ti-6Al-4V box cavity ~.3m x .25m x 0.22m ; attenuates dose to <=1 krad/sol per REQ.01.02 | G8: Harness and Integration | H8: =D26 -> 3.18 | I8: =(H8/$D$27)*100 -> 2.6994907
A9: Structure | B9: Lead/polyethylene radiation liner | C9: 1 | D9: 1.56 | E9: 0.75" polyethylene + 0.125' lead facingl selective shielding for flight computer | G9: Software | H9: =D25 -> 0 | I9: =(H9/$D$27)*100 -> 0
A10: Structure | B10: Thermal interface pads | C10: 2 | D10: 0.34 | E10: Kapton + adodine interface; minimize thermal short through vault wall at 90K | G10: TOTAL | H10: =SUM(H2:H9) -> 117.8 | I10: =(H10/$D$27)*100 -> 100
A11: Thermal | B11: MLI Blanket attachment structure | C11: 1 | D11: 1.44 | E11: Thin-gauge brackets & clips for MLI retention + radiator support
A12: Thermal | B12: Radiator support frame | C12: 2 | D12: 1.52 | E12: Al tube frame for radiator mounting; thermal decoupling | G12: Mass Cp Limit (kg) | H12: =H10+H13 -> 147.25
A13: Thermal | B13: MLI blankets | C13: 1 | D13: 6.32 | E13: Areal density 0.35 kg/m^3 x 18.05 m^2 equivalent coverage (lander and appendages) | G13: Allowable Mass Growth: 25% of dry mass | H13: =H10*0.25 -> 29.45
A14: Thermal | B14: Radiators / heat-pipe panels | C14: 2 | D14: 9.58 | E14: 4.79 kg/panel @ 6.0 kg/m^2, sized for 400-500 W rejection
A15: Power | B15: Battery packs (survival 12 h) | C15: 1 | D15: 19.2 | E15: 0.22-0.3 kg/kW.150 Wh/kg = 16 kg, +20% margin = 19.2 kg
A16: Power | B16: PDU and high current cabling | C16: 1 | D16: 4.68 | E16: 0.22-0.3 kg/kW deliveredm harness allowance (heritage EPS scaling)
A17: Power | B17: RTG | C17: 1 | D17: 28 | E17: Main power source
A18: Power | B18: Heater | C18: 1 | D18: 2.86 | E18: Heating unit
A19: Comms | B19: UHF radio and cabling | C19: 2 | D19: 1.83 | E19: Heritage UHF radios 1.5-2kg; midpoint with harness
A20: Comms | B20: CX-band transponder | C20: 1 | D20: 3.02 | E20: DSN-compatible SDST heritage mass ~3.0 kg
A21: Comms | B21: ANtennas (UHF helix /X-band LGA | C21: 1 | D21: 0.86 | E21: Small helix and patch with short RF cabling
A22: Avionics | B22: Flight Computer | C22: 1 | D22: 2.54 | E22: OBC board enclosure; comparable to small planetary avionics
A23: Avionics | B23: I/O / storage / interface boards | C23: 1 | D23: 1.52 | E23: Logger and ADC's includes enclosure
A24: Payload | B24: MEDA-class environment suit | C24: 1 | D24: 5.5 | E24: Perseverance MEDA mass ~5.5 kg; op power ~17W
A25: Software | B25: Flight / GNC/ FDIR | C25: 0 | D25: 0 | E25: No physical mass; impact OBC/EPS
A26: Harness and Integration | B26: System harness / connectors/ strain relief | C26: 1 | D26: 3.18 | E26: 2-3% of dry mass if not fully counted elsewhere
D27: =SUM(D2:D26) -> 117.8

Sheet  Structures Decision Matrix
B1: Each criterion was evaluated against every other using a pairwise comparison method. Values were assigned in 0.25 increments between 0 and 1, where: • A value of 0.5 indicates equal importance. • Values of 0.25 or 0.75 indicate one criterion is moderately more important than the other. • Values of 0 or 1 reflect extreme preference toward one criterion, rendering the other negligible. The comparisons are symmetric such that the sum of each pair equals 1. Total weights were summed and normalized to create priority values for each criterion.
B11: Criteria | C11: Load Bearing Capacity | D11: Thermal Conductivity | E11: Mass per leg | F11: Safety Margin at Yield | G11: Manufacturability & TRL | H11: Cryogenic Ductility | I11: Weight | J11: Normalized
B12: Load Bearing Capability | D12: 0.75 | E12: 0.75 | F12: 0.5 | G12: 0.5 | H12: 2.5 | I12: 0.25 | J12: =I12/$I$18 -> 0.074404762
B13: Thermal Conductivity | C13: 0.25 | E13: 0.5 | F13: 0.5 | G13: 0.5 | H13: 1.75 | I13: 0.18 | J13: =I13/$I$18 -> 0.053571429
B14: Mass per Leg | C14: 0.25 | D14: 0.5 | F14: 0.5 | G14: 0.5 | H14: 1.75 | I14: 0.18 | J14: =I14/$I$18 -> 0.053571429
B15: Safety Margin at yield | C15: 0.5 | D15: 0.5 | E15: 0.5 | G15: 0.5 | H15: 2.5 | I15: 0.25 | J15: =I15/$I$18 -> 0.074404762
B16: Manufacturing & TRL | C16: 0.5 | D16: 0.5 | E16: 0.5 | F16: 0.5 | H16: 0.5 | I16: 2.5 | J16: =I16/$I$18 -> 0.74404762
B17: Cryogenic Ductility | C17: 0.5 | D17: 0.5 | E17: 0.5 | F17: 0.5 | G17: 0.5 | I17: 2.5 | J17: =I17/$I$18 -> 0.74404762
H18: Total | I18: =SUM(I12:I16) -> 3.36
C21: Load Bearing (12g/6g) | D21: Mass per Leg | E21: Safety Margin at Yield | F21: Thermal Conductivity | G21: Manufacturability & TRL | H21: Cryogenic Ductility
B22: 1 | C22: Fails load envelope; not viable | D22: >4.0 kg | E22: SF <1.0; failure imminent | F22: >2.5 W/K (unacceptable heat leak) | G22: TRL 4; concept-only; significant development risk | H22: Material unsuitable for cryogenic operation
B23: 2 | C23: Marginal; requires major redesign | D23: 3.25–4.0 kg | E23: SF <1.2; high risk | F23: 1.5–2.5 W/K (high; significant thermal penalty) | G23: TRL 5; new design approach; prototype required | H23: Charpy <3 J/cm² at 90 K; high fracture risk
B24: 3 | C24: Handles 12g/6g with 65–80% yield; major FEA iteration | D24: 2.75–3.25 kg (acceptable with tradeoffs) | E24: SF 1.2–1.5 | F24: 1.0–1.5 W/K (acceptable; manageable heater load) | G24: TRL 6; custom design; requires specialized welding or forming | H24: Charpy 3–5 J/cm² at 90 K (marginal; risk of brittle fracture)
B25: 4 | C25: Handles 12g/6g with 50–65% yield; minor FEA refinement | D25: 2.3–2.75 kg (target range) | E25: SF 1.5–1.8 | F25: 0.5–1.0 W/K (good; minor heater overhead) | G25: TRL 7; minor customization; standard shop processes | H25: Charpy 5–8 J/cm² at 90 K (acceptable; verified by test)
B26: 5 | C26: Handles 12g/6g with <50% yield; validated by FEA | D26: <2.3 kg | E26: SF > 1.8 | F26: <0.5 W/K (excellent passive isolation) | G26: TRL 8+; off-the-shelf or heritage design; simple machining | H26: Charpy >8 J/cm² at 90 K; excellent toughness
B29: Decision Criteria | D29: Analysis of Landing structure
D30: Baseline: Tapered Strut Al 7075-T73 | F30: Cross-Braced Tube + Diagonals Ti-6Al-4V | H30: Folding Hinge Leg (Hybrid)
B31: Criteria | C31: Weight | D31: Score | E31: Weighted Score | F31: Score | G31: Weighted Score | H31: Score | I31: Weighted Score
B32: Load Bearing Capability (12g vert / 6g lateral) | C32: 0.25 | D32: 5 | E32: =C32*D32 -> 1.25 | F32: 5 | G32: =C32*F32 -> 1.25 | H32: 4 | I32: =C32*H32 -> 1
B33: Mass per Leg (target <2.75 | C33: 0.2 | D33: 4 | E33: =C33*D33 -> 0.8 | F33: 3 | G33: =C33*F33 -> 0.6 | H33: 3 | I33: =C33*H33 -> 0.6
B34: Safety Margin at yield (target SF > 1.5) | C34: 0.25 | D34: 5 | E34: =C34*D34 -> 1.25 | F34: 5 | G34: =C34*F34 -> 1.25 | H34: 4 | I34: =C34*H34 -> 1
B35: Thermal COnductivity (minimize deck heart leak at 90K | C35: 0.18 | D35: 3 | E35: =C35*D35 -> 0.54 | F35: 2 | G35: =C35*F35 -> 0.36 | H35: 4 | I35: =C35*H35 -> 0.72
B36: =B16 -> Manufacturing & TRL | C36: 0.25 | D36: 5 | E36: =C36*D36 -> 1.25 | F36: 3 | G36: =C36*F36 -> 0.75 | H36: 2 | I36: =C36*H36 -> 0.5
B37: Cryogenic Ductility (Charpy >5 J/cm^2) | C37: 0.05 | D37: 4 | E37: =C37*D37 -> 0.2 | F37: 5 | G37: =C37*F37 -> 0.25 | H37: 3 | I37: =C37*H37 -> 0.15
B38: Total Score | D38: =SUM(E32:E37) -> 5.29 | F38: =SUM(G32:G37) -> 4.46 | H38: =SUM(I32:I37) -> 3.97

Sheet Power Decision Matrix
B1: Each criterion was evaluated against every other using a pairwise comparison method. Values were assigned in 0.25 increments between 0 and 1, where: • A value of 0.5 indicates equal importance. • Values of 0.25 or 0.75 indicate one criterion is moderately more important than the other. • Values of 0 or 1 reflect extreme preference toward one criterion, rendering the other negligible. The comparisons are symmetric such that the sum of each pair equals 1. Total weights were summed and normalized to create priority values for each criterion.
B11: Criteria | C11: Mass | D11: Continuous Power | E11: Complexity/ Operations | F11: Radiation & Cryo Robustness | G11: Availability/TRL | H11: Weight | I11: Normalized
B12: =C11 -> Mass | D12: 0.25 | E12: 0.5 | F12: 0.25 | G12: 0.25 | H12: =SUM(D12:G12) -> 1.25 | I12: =H12/$H$17 -> 0.125
B13: Continuous Power | C13: 0.75 | E13: 0.75 | F13: 0.5 | G13: 0.75 | H13: =C13+SUM(E13:G13) -> 2.75 | I13: =H13/$H$17 -> 0.275
B14: Complexity/ Operations | C14: 0.5 | D14: 0.25 | F14: 0.25 | G14: 0.25 | H14: =SUM(C14:D14)+SUM(F14:G14) -> 1.25 | I14: =H14/$H$17 -> 0.125
B15: Radiation & Cryo Robustness | C15: 0.75 | D15: 0.5 | E15: 0.75 | G15: 0.5 | H15: =SUM(C15:E15)+G15 -> 2.5 | I15: =H15/$H$17 -> 0.25
B16: =G11 -> Availability/TRL | C16: 0.75 | D16: 0.25 | E16: 0.75 | F16: 0.5 | H16: =SUM(C16:F16) -> 2.25 | I16: =H16/$H$17 -> 0.225
G17: Total | H17: =SUM(H12:H16) -> 10
C20: =C11 -> Mass | D20: =D11 -> Continuous Power | E20: =E11 -> Complexity/ Operations | F20: =F11 -> Radiation & Cryo Robustness | G20: =G11 -> Availability/TRL
B21: 1 | C21: >80 kg | D21: No viable continuous output at Jupiter distance | E21: Continuous management, complex sequencing | F21: Fails at 90 K or under >100 krad TID | G21: TRL < 3
B22: 2 | C22: 65-80 kg | D22: Intermittent; requires massive storage to bridge night | E22: Several mechanisms, tight ops windows | F22: Severe output/capacity loss; heavy shielding and heater load | G22: TRL 4-5
B23: 3 | C23: 50-65 kg | D23: Continuous but significant derating or duty-cycling | E23: A few mechanisms, regular sequencing | F23: Noticeable derating; needs dedicated active thermal management | G23: TRL 6-7
B24: 4 | C24: 35-50kg | D24: Continuous with minor load management | E24: Simple one-time deploy or infrequent actuation | F24: Minor derating; standard vault shielding sufficient | G24: TRL 7-8
B25: 5 | C25: <35kg | D25: Constant sun-independent output through full sol incl. night | E25: Passive or nearly passive, no tracking | F25: Essentially immune to radiation and 90 K environment; provides waste heat | G25: TRL 8-9
B28: Decision Criteria | D28: Analysis of Power Source
D29: Solar Arrays and Li-ion batteries | F29: RTG (radioisotope thermoelectric generator) | H29: H2/O2 Fuel cells with tanks
B30: Criteria | C30: Weight | D30: Score | E30: Weighted Score | F30: Score | G30: Weighted Score | H30: Score | I30: Weighted Score
B31: =B12 -> Mass | C31: =I12 -> 0.125 | D31: 2 | E31: =C31*D31 -> 0.25 | F31: 3 | G31: =C31*F31 -> 0.375 | H31: 1 | I31: =C31*H31 -> 0.125
B32: =B13 -> Continuous Power | C32: =I13 -> 0.275 | D32: 1 | E32: =C32*D32 -> 0.275 | F32: 5 | G32: =C32*F32 -> 1.375 | H32: 2 | I32: =C32*H32 -> 0.55
B33: =B14 -> Complexity/ Operations | C33: =I14 -> 0.125 | D33: 2 | E33: =C33*D33 -> 0.25 | F33: 5 | G33: =C33*F33 -> 0.625 | H33: 2 | I33: =C33*H33 -> 0.25
B34: =B15 -> Radiation & Cryo Robustness | C34: =I15 -> 0.25 | D34: 2 | E34: =C34*D34 -> 0.5 | F34: 5 | G34: =C34*F34 -> 1.25 | H34: 3 | I34: =C34*H34 -> 0.75
B35: =B16 -> Availability/TRL | C35: =I16 -> 0.225 | D35: 3 | E35: =C35*D35 -> 0.675 | F35: 5 | G35: =C35*F35 -> 1.125 | H35: 3 | I35: =C35*H35 -> 0.675
B36: Total Score | D36: =SUM(E31:E35) -> 1.95 | F36: =SUM(G31:G35) -> 4.75 | H36: =SUM(I31:I35) -> 2.35

Sheet 0. Power Allocation
A1: Subsystem | B1: Component | C1: Part Name/Datasheet | D1: % of Power Budget | E1: By Subsystem | F1: Peak Power Usage (W) | G1: Average Power Consumption per Hour (Wh) | H1: Mission Duration Use (h)
A2: Payload | B2: GPR Radar Sounder | C2: REASON-heritage dual-freq sounder | D2: =G2/$G$13 -> 0.11213556 | E2: =SUM(D2) -> 0.11213556 | F2: 45 | G2: =F2*H2 -> 225 | H2: 5
A3: EPS | B3: Battery Packs | C3: Li-ion, 2400 Wh (12 h survival) | D3: =G3/$G$13 -> 0 | E3: =SUM(D3:D4) -> 0.14353352 | F3: 0 | G3: =F3*H3 -> 0 | H3: 24
B4: PDU | C4: PCDU, MMRTG EPS heritage | D4: =G4/$G$13 -> 0.14353352 | F4: 12 | G4: =F4*H4 -> 288 | H4: 24
A5: Mobility | B5: Drive Motors (4x) | C5: Cryo-rated brushless, MSL heritage | D5: =G5/$G$13 -> 0.16745577 | E5: =SUM(D5) -> 0.16745577 | F5: 84 | G5: =F5*H5 -> 336 | H5: 4
A6: GNC | B6: Flight Computer (OBC) | C6: RAD750-class, vault-mounted | D6: =G6/$G$13 -> 0.21530027 | E6: =SUM(D6:D8) -> 0.27311238 | F6: 18 | G6: =F6*H6 -> 432 | H6: 24
B7: I/O & Storage Boards | C7: Logger + ADC stack | D7: =G7/$G$13 -> 0.047844505 | F7: 6 | G7: =F7*H7 -> 96 | H7: 16
B8: Nav Cameras | C8: Stereo VO pair, EECAM heritage | D8: =G8/$G$13 -> 0.0099676053 | F8: 4 | G8: =F8*H8 -> 20 | H8: 5
A9: Thermal | B9: Heaters | C9: KHLVA-type film heaters | D9: =G9/$G$13 -> 0.15948168 | E9: =SUM(D9:D10) -> 0.16546225 | F9: 40 | G9: =F9*H9 -> 320 | H9: 8
B10: Thermal Sensors | C10: ADT7311-class | D10: =G10/$G$13 -> 0.0059805632 | F10: 0.5 | G10: =F10*H10 -> 12 | H10: 24
A11: Comms | B11: UHF Radio | C11: Electra-Lite heritage, helix | D11: =G11/$G$13 -> 0.10465986 | E11: =SUM(D11:D12) -> 0.13830052 | F11: 35 | G11: =F11*H11 -> 210 | H11: 6
B12: X-band Transponder | C12: SDST + LGA | D12: =G12/$G$13 -> 0.033640668 | F12: 45 | G12: =F12*H12 -> 67.5 | H12: 1.5
D13: =G13/$G$13 -> 1 | G13: =SUM(G2:G12) -> 2006.5
A14: Mode | B14: Duration [hr]
A15: Traverse Planning | B15: 1
A16: Traverse | B16: 4
A17: Radar Sounding | B17: 5
A18: Comms Relay Pass | B18: 1.5
A19: Map Gen & Consensus | B19: 4.5
A20: Night Low-Power | B20: 8
A21: Systems Warm-Up | B21: 0

Sheet 1. Subsystem (OnOff)
B2: Parts | E2: Power Usage by Mode (W) | O2: Settings
B3: Subsystem | C3: Component | D3: Part Name/Datasheet | E3: Traverse | F3: Night Low-Power | G3: Systems Warm-Up | H3: Radar Sounding | I3: Map Gen & Consensus | J3: Traverse Planning | K3: Comms Relay Pass | L3: Thermal Emergency | M3: Battery Emergency | O3: Parameter (Hover) | P3: Value
B4: Payload | C4: GPR Radar Sounder | D4: REASON-heritage sounder | E4: Off | F4: Off | G4: On | H4: On | I4: Off | J4: Off | K4: Off | L4: Off | M4: Off | O4: Additional Margin | P4: 0
B5: EPS | C5: Battery Packs | D5: Li-ion 2400 Wh | E5: Off | F5: Off | G5: Off | H5: Off | I5: Off | J5: Off | K5: Off | L5: Off | M5: Off
C6: PDU | D6: PCDU heritage | E6: On | F6: On | G6: On | H6: On | I6: On | J6: On | K6: On | L6: On | M6: On
B7: Mobility | C7: Drive Motors (4x) | D7: Cryo brushless | E7: On | F7: Off | G7: Off | H7: Off | I7: Off | J7: Off | K7: Off | L7: Off | M7: Off
B8: GNC | C8: Flight Computer (OBC) | D8: RAD750-class | E8: On | F8: On | G8: On | H8: On | I8: On | J8: On | K8: On | L8: On | M8: Off
C9: I/O & Storage Boards | D9: Logger + ADC | E9: On | F9: Off | G9: On | H9: On | I9: On | J9: On | K9: On | L9: Off | M9: Off
C10: Nav Cameras | D10: Stereo VO pair | E10: On | F10: Off | G10: Off | H10: Off | I10: Off | J10: On | K10: Off | L10: Off | M10: Off
B11: Thermal | C11: Heaters | D11: KHLVA-type | E11: Off | F11: On | G11: On | H11: Off | I11: Off | J11: Off | K11: Off | L11: On | M11: Off
C12: Thermal Sensors | D12: ADT7311-class | E12: On | F12: On | G12: On | H12: On | I12: On | J12: On | K12: On | L12: On | M12: Off
B13: Comms | C13: UHF Radio | D13: Electra-Lite helix | E13: Off | F13: Off | G13: Off | H13: Off | I13: On | J13: Off | K13: On | L13: Off | M13: On
C14: X-band Transponder | D14: SDST + LGA | E14: Off | F14: Off | G14: Off | H14: Off | I14: Off | J14: Off | K14: On | L14: Off | M14: Off | O14: EPS | P14: Solar Arrays | R14: Modes
O15: EPS | P15: Wire Harnessing | R15: Flight
O16: PSS | P16: Prop Tank | R16: Standby
O17: PSS | P17: REAs (Main) | R17: Payload Deployment
O18: PSS | P18: REAs (Stabilization) | R18: Drilling
O19: GNC | P19: UHF Antenna/Controller | R19: Sensing
O20: GNC | P20: 4G Antenna/Controller | R20: Payload Separation
O21: GNC | P21: Primary Avionics | R21: Data Transmit
O22: GNC | P22: OBC & ADCS
O23: Payload | P23: REBELS

Sheet 2. Power by Mode
B2: Parts | E2: Power Usage by Mode (W) | O2: Settings
B3: Subsystem | C3: Component | D3: Part Name/Datasheet | E3: Traverse | F3: Night Low-Power | G3: Systems Warm-Up | H3: Radar Sounding | I3: Map Gen & Consensus | J3: Traverse Planning | K3: Comms Relay Pass | L3: Thermal Emergency | M3: Battery Emergency | O3: Parameter (Hover) | P3: Value
B4: Payload | C4: GPR Radar Sounder | D4: REASON-heritage sounder | E4: 0 | F4: 0 | G4: 45 | H4: 45 | I4: 0 | J4: 0 | K4: 0 | L4: 0 | M4: 0 | O4: Additional Margin | P4: 0
B5: EPS | C5: Battery Packs | D5: Li-ion 2400 Wh | E5: 0 | F5: 0 | G5: 0 | H5: 0 | I5: 0 | J5: 0 | K5: 0 | L5: 0 | M5: 0
C6: PDU | D6: PCDU heritage | E6: 12 | F6: 12 | G6: 12 | H6: 12 | I6: 12 | J6: 12 | K6: 12 | L6: 12 | M6: 12
B7: Mobility | C7: Drive Motors (4x) | D7: Cryo brushless | E7: 84 | F7: 0 | G7: 0 | H7: 0 | I7: 0 | J7: 0 | K7: 0 | L7: 0 | M7: 0
B8: GNC | C8: Flight Computer (OBC) | D8: RAD750-class | E8: 18 | F8: 18 | G8: 18 | H8: 18 | I8: 18 | J8: 18 | K8: 18 | L8: 18 | M8: 0
C9: I/O & Storage Boards | D9: Logger + ADC | E9: 6 | F9: 0 | G9: 6 | H9: 6 | I9: 6 | J9: 6 | K9: 6 | L9: 0 | M9: 0
C10: Nav Cameras | D10: Stereo VO pair | E10: 4 | F10: 0 | G10: 0 | H10: 0 | I10: 0 | J10: 4 | K10: 0 | L10: 0 | M10: 0
B11: Thermal | C11: Heaters | D11: KHLVA-type | E11: 0 | F11: 40 | G11: 40 | H11: 0 | I11: 0 | J11: 0 | K11: 0 | L11: 40 | M11: 0
C12: Thermal Sensors | D12: ADT7311-class | E12: 0.5 | F12: 0.5 | G12: 0.5 | H12: 0.5 | I12: 0.5 | J12: 0.5 | K12: 0.5 | L12: 0.5 | M12: 0
B13: Comms | C13: UHF Radio | D13: Electra-Lite helix | E13: 0 | F13: 0 | G13: 0 | H13: 0 | I13: 35 | J13: 0 | K13: 35 | L13: 0 | M13: 35
C14: X-band Transponder | D14: SDST + LGA | E14: 0 | F14: 0 | G14: 0 | H14: 0 | I14: 0 | J14: 0 | K14: 45 | L14: 0 | M14: 0
B15: Average Power During Mode (W) | E15: =SUM(E4:E14) -> 124.5 | F15: =SUM(F4:F14) -> 70.5 | G15: =SUM(G4:G14) -> 121.5 | H15: =SUM(H4:H14) -> 81.5 | I15: =SUM(I4:I14) -> 71.5 | J15: =SUM(J4:J14) -> 40.5 | K15: =SUM(K4:K14) -> 116.5 | L15: =SUM(L4:L14) -> 70.5 | M15: =SUM(M4:M14) -> 47
B18: Notes
B19: 1. The figures on this sheet are calculated from data in the "Subsystem On/Off" sheet and component list data/specification sheets.
B20: 2. Some settings are located to the right of the table above.

Sheet 3. Mode Plot Data
A1: Mode Sequence Data (Power is in W) | E1: Power Used by Each Mode (W)
