Workbook

Sheet M.S. & Objectives
B1: Level | C1: OBJECTIVES & REQUIREMENTS | D1: Objective or Requirement Statement | E1: Date Last Updated | F1: Source(s) | G1: System/ Subsystem(s) Affected? | H1: Status? | I1: CHANGE LOG | J1: Revisions to the Objective/ Requirement | K1: Reasons/ Justification | L1: Source(s) | M1: ASSOCIATED RISKS | N1: Associated Risks with Requirement | O1: VERIFICATION & VALIDATION (V&V) | P1: Testing Method | Q1: Verification Plan | R1: Validation Plan | S1: Any Pre-Actions Needed?
A2: OBJ = Objective, REQ = Requirement, CSR = Constraint. Number Hierarchy = 01.02.03 (01 = Objective Parent Category, 02 = First Child Requirement, 03 = Second Child Requirement... etc) | B2: System, Subsystem, or Component Level? | D2: Full statement sentence. Objectives are the requirements in simple, easy to understand, general terms. Requirements are technical as "shall" statements with a specific, measureable, and testable guideline to be met. | E2: Date of when the requirement statement was last revised. | F2: Where did this requirement come from? Is this based on literature, stakeholder, testing standards, etc? Include links if possible. | G2: Does this matter on a system level? If not, which subsystems does this directly affect? Consider the interfaces as well. Which subsystems are responsible? | H2: Accomplished or unaccomplished? | J2: List by chronological order, with most recent revisions FIRST. Include... (year.month.date) Revision 1 comment, (year.month.date) Revision 2 comment | K2: Why was the revision made? | N2: List the associated risk numbers. | Q2: Verification - Does it meet the specification need? Are we building our product right? | R2: Validation - Does it meet the customer need? Did we build the right product?
A3: MISSION STATEMENT | B3: MISSION STATEMENT | D3: The multi-agent Europa surface system shall autonomously characterize the ice shell and identify a cryobot insertion site, operating without real-time Earth support. | E3: 46187 | F3: - | G3: - | H3: -
A4: OBJ.01 | B4: System Level | D4: The system shall demonstrate autonomous multi-agent coordination and consensus-based decision making without Earth communication links | E4: 46187 | F4: This objective addresses the multi-agent coordination shortfall ranked 139th in NASA's Civil Space Technology Shortfall Rankings, which identifies cooperative task planning as a near-term priority (STMD]
A5: OBJ.02 | B5: Subsystem Mobility | D5: The rover shall traverse Europa's surface terrain and maintain localization using onboard sensors and inter-agent ranging | E5: 46187 | F5: This objective addresses NASA's identified gap in autonomous navigation without Earth-based support, as stated in the FY 2026-2027 SBIR solicitation Topic COMNAV.1.S26B [SBIR]
A6: OBJ.03 | B6: Subsystem Science/Payload | D6: The system shall characterize ice shell thickness using a ground penetrating radar sounder and identify candidate insertion sites | E6: 46187 | F6: This objective supports the science goals outlined in the Decadal Survey, which identifies Europa's subsurface ocean as a primary target for astrobiology and calls for characterization of the ice shell to assess habitability. [OWL]
A7: OBJ.04 | B7: Subsystem COMMs | D7: The inter-agent mesh network shall maintain coordination under degraded connectivity and radiation induced faults | E7: 46187 | F7: This objective addresses NASA's identified gap in autonomous distributed spacecraft operations without Earth-based navigational support, per SBIR Topic COMNAV.1.S26B. [SBIR]

Sheet Requirements
B1: Level | C1: OBJECTIVES & REQUIREMENTS | D1: Objective or Requirement Statement | E1: Date Last Updated | F1: Reasoning | G1: Source(s) | H1: System/ Subsystem(s) Affected? | I1: Status? | J1: CHANGE LOG | K1: Revisions to the Objective/ Requirement | L1: Reasons/ Justification | M1: Source(s) | N1: ASSOCIATED RISKS | O1: Associated Risks with Requirement | P1: VERIFICATION & VALIDATION (V&V) | Q1: Testing Method | R1: Verification Plan | S1: Validation Plan | T1: Any Pre-Actions Needed? | U1: Notes For Final Presentation.
A2: OBJ = Objective, REQ = Requirement, CSR = Constraint. Number Hierarchy = 01.02.03 (01 = Objective Parent Category, 02 = First Child Requirement, 03 = Second Child Requirement... etc) | B2: System, Subsystem, or Component Level? | D2: Full statement sentence. Objectives are the requirements in simple, easy to understand, general terms. Requirements are technical as "shall" statements with a specific, measureable, and testable guideline to be met. | E2: Date of when the requirement statement was last revised. | G2: Where did this requirement come from? Is this based on literature, stakeholder, testing standards, etc? Include links if possible. | H2: Does this matter on a system level? If not, which subsystems does this directly affect? Consider the interfaces as well. Which subsystems are responsible? | I2: Accomplished or unaccomplished? | K2: List by chronological order, with most recent revisions FIRST. Include... (year.month.date) Revision 1 comment, (year.month.date) Revision 2 comment | L2: Why was the revision made? | O2: List the associated risk numbers. | R2: Verification - Does it meet the specification need? Are we building our product right? | S2: Validation - Does it meet the customer need? Did we build the right product? | U2: What work did you do for this requirement this semester
A3: REQ.01.01 | B3: System [Mission level] | D3: The multi-agent Europa system shall operate fully autonomously for the entire surface mission duration without requiring real-time command uplinks from Earth. | E3: 46187 | F3: The 44-minute one-way light delay between Earth and Jupiter makes real-time demanding physically impossible, all decisions must be onboard. Traceable to OBJ.01 | G3: NASA FY 2026-2027 SBIR Solicitation, Topic COMNAV.1.S26B, 2025 | H3: System | I3: Unaccomplished | O3: Risk-01: Single-point autonomy failure with no fallback human override | Q3: Hardware-in-the-loop simulation. Run a 72-hour autonomous mission sequence with a simulated 44-min communication blackout, and verify zero unresolved command dependencies on Earth. | R3: Verify the software autonomously executes all planned traverses, consensus rounds, and science data collected without any Earth uplink during the blackout window. | S3: Demonstrate that the mission objectives are achieved across three independent HILL runs without Earth support
A4: REQ.01.02 | B4: System [Mission level] | D4: The system shall survive and maintain operational status after exposure to total ionizing dose of no less than 100 krad over the nominal mission lifetime. | E4: 46187 | F4: Jupiter's magnetosphere delivers radiation doses far exceeding near-Earth missions. Europas Clipper';s radiation vault architecture targets ~100 krad as the design threshold. Radiation environment directly drives the shielded vault requirement. Traceable to OBJ.01 | G4: National Academies, Origins Worlds and Life Decadal Survey 2023–2032, https://www.nationalacademies.org/read/26522; Galileo spacecraft radiation vault design heritage | H4: System; Electronics; Power | I4: Unaccomplished | O4: RISK-02: Accumulated single event upsets degrade consensus algorithm convergence before mission completion. | Q4: Co-60 gamma irradiation of all radiation-sensitive components to 110 krad (10% margin). Monitor functional performance throughout exposure. | R4: Verify all components pass functional tests at end of life dose with no loss of required functionality | S4: Validate the integrated rover and relay nodes complete simulated mission operations after TID exposure.
A5: REQ.01.03 | B5: System [Mission level] | D5: The system shall maintain a minimum inter-agent network connectivity of two active relay nodes at all times during surface operations to ensure consensus is achievable. | E5: 46187 | F5: Consensus algorithms require a minimum connected graph to guarantee convergence. Two active relays plus a surface rover guarantee a 3-node connected topology as the minimum viable configuration. Traceable to OBJ.01 and OBJ.04. | G5: NASA STMD Civil Space Technology Shortfall Rankings, Jul. 2024, https://www.nasa.gov/wp-content/uploads/2024/07/civil-space-shortfall-ranking-july-2024.pdf | H5: System; COMMs | I5: Unaccomplished | O5: RISK-03: Simultaneous radiation-induced failure of multiple relay nodes isolating the surface rover. | Q5: Network fault simulation: simulate progressive relay node failures and verify consensus detects degenerated topology and triggers reconfiguration before dropping below 2 active nodes. | R5: Verify that fault detection and reconfiguration logic activates within one consensus cycle period upon detection of a node loss event. | S5: Validate that the surface rover completes a traverse plan using map data from a degraded 2-relay configuration.
A6: REQ.02.01 | B6: Subsystems [Operations Level] Mobility | D6: The surface robot shall maintain a localization accuracy of no worse than +-0.5 m relative to its last known position during any traverse segments up to 50 m in the absence of GPS. | E6: 46187 | F6: Cryobot insertion site selection requires meter-level positioning to match the radar identified thin ice candidate. +-0.5 over 59 m segments in consistent with visual odometry performance on Mars rovers. Traceable to OBJ.02 | G6: NASA FY 2026-2027 SBIR Solicitation, Topic COMNAV.1.S26B; Mars Curiosity rover visual odometry heritage | H6: Mobility; GNC | I6: Unaccomplished | O6: RISK-04: Ice surface texture homogeneity reducing visual odometry feature tracking quality. | Q6: Field test on analog terrain: command 50m traverse segments and compare onboard state estimate to ground truth GPSD position across 20 runs under varying terrain conditions. | R6: verify that position error remains within +-0.5 m across a minimum of 20 traverse segments. | S6: Validate that the rover navigates to and stops within +-0.5 m of a designated waypoint representing a candidate insertion site.
A7: REQ.03.01 | B7: Subsystems [Operations Level] Science / Payload | D7: The ground-penetrating radar sounder shall resolve ice shell thickness to within +-10% accuracy for ice layers between 1 km and 30 km depth, producing a subsurface map at the minimum spatial resolution of 100 m along the traverse track. | E7: 46187 | F7: Identifying optimal cryobot insertion site requires knowing where the ice shell is the thinnest. +- 10% thickness accuracy is enough to distinguish viable drilling candidates. The 100 m along track resolution is consistent with the Europa Clipper REASON instrument design parameters. Traceable to OBJ.03 | G7: National Academies, Origins Worlds and Life Decadal Survey 2023–2032, https://www.nationalacademies.org/read/26522; Europa Clipper REASON instrument documentation | H7: Science/Payload, Power | I7: Unaccomplished | O7: RISK-05: Ice shell heterogeneity or brine inclusions creating radar clutter that degrades thickness estimates. | Q7: Laboratory radar range measurements against ice targets of known thickness using dielectric matches analogs, verify +- 10% accuracy across the 1-30 km depth range. | R7: Verify that the radar sounder produces subsurface profiles with +-10% depth accuracy against calibration targets before rover integration. | S7: Validate that the subsurface map produces during a field traverse correctly identifies presurveyed thin ice candidate sites within the required spatial resolution.
A8: REQ.04.01 | B8: Subsystems [Operations Level] COMMS | D8: The inter-agent mesh network shall achieve consensus on a shared consensus on a shared terrain map update within no more than 10 minutes under a degraded network condition defined as packet loss rates of up to 30% on any single inter-agent link | E8: 46187 | F8: Rover traverse planning depends on a current consensus validated terrain map. A 10 minute convergence bound limits traverse planning delay to an acceptable operations cadence. 30% packet loss represents a plausible radiation induced degradation scenario for the environment. Traceable to OBJ.04. | G8: NASA STMD Civil Space Technology Shortfall Rankings, Jul. 2024; NASA FY 2026-2027 SBIR Solicitation, Topic COMNAV.1.S26B | H8: COMMs, CDH | I8: Unaccomplished | O8: RISK-06: Radiation induced burst errors exceeding 30% packet loss on multiple links simultaneously, stalling consensus. | Q8: Software-in-the-loop consensus simulation: Introduce 30% packet loss on each inter-agent link and measure convergence time across 100 test runs. | R8: Verify the consensus convergence time remains <10 minutes across all 100 test runs with 30% packet loss. | S8: Validate that the rover initiates a traverse using a map update produced by the consensus protocol under the degraded link test condition.
A9: REQ.03.02 | B9: Subsystems [Operation Level} Science / payload | D9: The radar sounder antenna shall be mounted such that the antenna boresight remains within +-5 of nadir during all active sounding operations; the rover shall halt traversal if the measured surface slope exceeds 20 to maintain pointing compliance. | E9: 46189 | F9: A nadir pointing antenna is required to minimize geometric error in the two-way travel time measurement. . Off nadir tilt reduces basal reflection return strength and introduces range error that degrades | G9: National Academies, Origins Worlds and Life Decadal Survey 2023–2032; Europa Clipper REASON instrument documentation | H9: Science/Payload; Structures; Mobility | I9: Unaccomplished | O9: RISK-05: Ice shell heterogeneity creating radar clutter that degrades thickness estimates; RISK-04: Ice surface texture reducing visual odometry quality (slope-stop logic dependency) | Q9: Bench test antenna mounting fixture: tilt rover chassis to 5° increments and measure antenna boresight deviation using an inclinometer. Verify pointing error stays within ±5° across the full range of surface slopes up to 20°. | R9: Verify that antenna boresight deviation does not exceed ±5° of nadir across all chassis tilt angles up to 20° slope | S9: Validate that the rover correctly halts traversal and resumes sounding when slope threshold is exceeded during an analog terrain field test.
A10: REQ.03.03 | B10: Subsystems [Operations Level] Science / Payload | D10: The rover power subsystem shall reserve a dedicated peak power allocation for radar sounder transmission pulses and shall command drive motor shutdown during each active sounding window to prevent power contention with the RTG continuous output. | E10: 46189 | F10: Radar sounders draw high peak pulse power during transmission. The RTG provides fixed continuous output; simultaneous drive and sounding would exceed available power margin and risk under-powering the radar pulse, degrading return signal amplitude below the noise floor. Stop-and-sound is consistent with high-power instrument operation heritage on Mars rovers. Traceable to OBJ.03. | G10: Europa Clipper REASON instrument documentation; NASA RTG power system heritage | H10: Science/Payload; Power; Mobility | I10: Unaccomplished | O10: RISK-02: Accumulated single event upsets degrade system performance; RISK-05: Degraded radar return amplitude from insufficient transmission power | Q10: Hardware-in-the-loop power budget simulation: command simultaneous drive and sounding operations and monitor RTG output margin across 50 test cycles. Verify drive shutdown command fires before each sounding pulse. | R10: Verify that drive motors are commanded off prior to every sounding transmission and that RTG output margin remains positive across all test cycles. | S10: Validate that the rover completes a full simulated traverse sol with correct stop-and-sound behavior and no power fault events.
A11: REQ.03.04 | B11: Subsystems [Operations Level] Science / Payload | D11: The command and data handling subsystem shall provide onboard storage sufficient to retain a minimum of 7 sols of uncompressed radar trace data, and shall apply lossless compression to all Radar_Traces records prior to inter-agent relay transmission, achieving a minimum compression ratio of 2:1. | E11: 46189 | F11: At approximately 40 traces per sol across four data sheets, raw science data accumulates faster than the non-deterministic Earth relay can downlink. Seven sols of buffer covers the consensus convergence window and plausible communication gaps. Lossless compression preserves the measurement fidelity required by REQ.03.01 while reducing relay load. Traceable to OBJ.03 and OBJ.04. | G11: NASA STMD Civil Space Technology Shortfall Rankings, Jul. 2024; Europa Clipper REASON instrument documentation | H11: Science/Payload; COMMs; CDH | I11: Unaccomplished | O11: RISK-06: Radiation induced burst errors exceeding 30% packet loss stalling consensus; RISK-05: Ice shell heterogeneity generating excess CLUTTER traces inflating data volume | Q11: Software-in-the-loop storage simulation: generate 7 sols of synthetic radar trace data at full volume and verify onboard storage does not overflow. Apply compression algorithm and measure output ratio across 100 data sets. | R11: Verify that onboard storage accommodates 7 sols of uncompressed data and that compression ratio meets or exceeds 2:1 across all 100 test data sets. | S11: Validate that compressed science data downlinked through the inter-agent mesh under 30% packet loss conditions can be fully reconstructed without data loss on the receiving node.

Sheet Payload
A1: Timestamp_UTC | B1: Sol | C1: Pressure_mbar | D1: AirTemp_C | E1: GroundTemp_C | F1: Humidity_pct | G1: WindSpeed_mps | H1: WindDir_deg | I1: Dust_OpticalDepth | J1: Radiation_Wm2 | K1: Data_Quality_Flag

Sheet ImplementationStatus
A1: Level | B1: Requirement No. | C1: Source | D1: Requirement | E1: Implementation | F1: Validation Before TVC | G1: Status (MET/ WIP/ UNMET) | H1: Date Last Updated | I1: Instructions (do not copy this column)
A2: =Requirements!B3 -> System [Mission level] | B2: =Requirements!A3 -> REQ.01.01 | I2: Do not edit Columns A - C. To update them, use the "Requirements" sheet.
A3: =Requirements!B12 | B3: =Requirements!A12 | I3: In Column A, look for your subsystem's requirements.
A4: =#REF! -> #REF! | B4: =#REF! -> #REF! | I4: In Column D, state how you are implementing design / assembly / integration / testing plans to meet the requirement.
A5: =#REF! -> #REF! | B5: =#REF! -> #REF! | I5: In Column E, state the status - if the Requirement is Met, Unmet, or a Work in Progress (WIP) based on the Implementation description.
A6: =Requirements!B13 | B6: =Requirements!A13 | I6: Be sure to state in Column F if the Implementation/Status has been updated.
A7: =Requirements!B14 | B7: =Requirements!A14
A8: =#REF! -> #REF! | B8: =#REF! -> #REF!
A9: =#REF! -> #REF! | B9: =#REF! -> #REF!
A10: =Requirements!B15 | B10: =Requirements!A15
A11: =Requirements!B16 | B11: =Requirements!A16
A12: =Requirements!B17 | B12: =Requirements!A17
A13: =Requirements!B18 | B13: =Requirements!A18
A14: =#REF! -> #REF! | B14: =#REF! -> #REF!
A15: =#REF! -> #REF! | B15: =#REF! -> #REF!
A16: =#REF! -> #REF! | B16: =#REF! -> #REF!
A17: =#REF! -> #REF! | B17: =#REF! -> #REF!
A18: =#REF! -> #REF! | B18: =#REF! -> #REF!
A19: =#REF! -> #REF! | B19: =#REF! -> #REF!
A20: =#REF! -> #REF! | B20: =#REF! -> #REF!
A21: =#REF! -> #REF! | B21: =#REF! -> #REF!
A22: =#REF! -> #REF! | B22: =#REF! -> #REF!
A23: =#REF! -> #REF! | B23: =#REF! -> #REF!
A24: =#REF! -> #REF! | B24: =#REF! -> #REF!
A25: =#REF! -> #REF! | B25: =#REF! -> #REF!
... A39: =#REF! -> #REF! | B39: =#REF! -> #REF!

Sheet Outline Key Phases of the Missi
A1: Time (UTC or Mission Elapsed Time) | B1: Robot Function / Mode | C1: Primary Objective / Milestone | D1: Operation Mode (Teleop / Autonomous / Semi-Autonomous / Scripted) | E1: Inputs (e.g., command, signal, state) | F1: Expected Outputs (e.g., telemetry, sensor data) | G1: Data Products Generated | H1: Verification Method | I1: Associated Risk or Sensitivity (High/Med/Low) | J1: Dependencies / Predecessor Actions | K1: Estimated Duration | L1: Notes
A2: Launch day, 0-1 (Mission Elapsed Time) | B2: Launch And Commissioning | C2: Spacecraft Separation and initial health checks | D2: Scripted/Autonomous | E2: Launch vehicle separation signal, onboard startup sequences | F2: Spacecraft status telemetry, power system telemetry, communication link confirmation | G2: Initial spacecraft health report, subsystem status logs | H2: Verify successful separation communication establishment, and nominal subsystem health/ | I2: High | J2: Successful vehicle loading and spacecraft deployment | K2: 1 day
A3: Cruise Phase, Years 0-6 | B3: Cruise And Approach | C3: Maintain spacecraft health and perform trajectory correction maneuvers | D3: Semi-Autonomous | E3: Ground-planned trajectory updates, star tracker measurements, navigation state estimates | F3: Navigation telemetry, spacecraft health telemetry, maneuver confirmation | G3: Trajectory correction logs, navigation solution history | H3: Verify trajectory remains within mission tolerance and all spacecraft systems remain operational | I3: Medium | J3: Completion of launch and commision phase | K3: ~6 years
A4: Europa Orbital Insertion and Reconnaissance | B4: Europa Orbit Insertion And Orbital Reconnaissance | C4: Deploy orbital agents and identify suitable landing region | D4: Autonomous | E4: Orbital state estimates, terrain imaging data, radar survey measurements | F4: Surface maps, hazard maps, candidate landing sites | G4: Global terrain map, landing site assessment report | H4: Verify successful orbital insertion, orbiter deployment, and identification of viable landing zones. | I4: High | J4: Successful arrival at Europa and orbital insertion burn | K4: 30 Days
A5: Surface Operations Day 0-5 | B5: Landing, Surface Checkout, And Site Characterization | C5: Deploy rover, verify system health, and calibrate science instruments. | D5: Autonomous | E5: Landing state, rover deployment commands, sensor calibration routines | F5: Health telemetry, localization estimates, calibration measurements | G5: System checkout report, calibration datasets, local terrain map | H5: Verify successful rover deployment, communications, localization accuracy, and payload calibration | I5: High | J5: Reconnaissance complete and landing site selected | K5: 5 Days
A6: Surface Operations Day 5-35 | B6: Surface Survey And Ice Characterization | C6: Map subsurface ice structure and identify candidate cryobot insertion sites | D6: Autonomous | E6: Ground-penetrating radar returns, orbital terrain map, localization state estimations | F6: Ice thickness estimates, terrain classifications, rover position estimates | G6: Subsurface radar maps, ice thickness profiles, candidate cryobot site database, consensus terrain maps | H6: Verify radar measurements meet required accuracy and candidate sites satisfy mission selection criteria | I6: Medium | J6: Successful rover deployment and payload calibration | K6: 30 Days
A7: Surface Operations Day 35-50 | B7: Data Transmission And End Of Mission | C7: Downlink mission data, select final cryobot site, and safely passivate system | D7: Semi-Autonomous | E7: Stored science data, final site selection results, mission completion commands | F7: Mission archive transmission, final health telemetry, passivation confirmation | G7: Final mission report, validated cryobot insertion site package, complete science archive | H7: Verify all science data successfully transmitted and spacecraft enters safe passivated state | I7: Low | J7: Completion of science objectives and final site selection | K7: 15 days

Sheet Concept of Operations Timeline
A1: Time (UTC or Mission Elapsed Time) | B1: Robot Function / Mode | C1: Primary Objective / Milestone | D1: Operation Mode (Teleop / Autonomous / Semi-Autonomous / Scripted) | E1: Inputs (e.g., command, signal, state) | F1: Expected Outputs (e.g., telemetry, sensor data) | G1: Data Products Generated | H1: Verification Method | I1: Associated Risk or Sensitivity (High/Med/Low) | J1: Dependencies / Predecessor Actions | K1: Estimated Duration | L1: Notes
A2: Launch Day | B2: Launch & Commission | C2: Deploy Spacecraft And Establish Communications | D2: Scripted/Autonomous | E2: Launch separation signal, startup sequences | F2: Telemetry, power status, comm link | G2: Initial health report | H2: Verify separation and subsystem health | I2: High | J2: Launch vehicle deployment | K2: 1 day | L2: Mission Start
A3: Cruise Years 1-6 | B3: Cruise & Approach | C3: Transit To Europa | D3: Semi-Autonomous | E3: Navigation measurements, trajectory updates | F3: Navigation telemetry | G3: Trajectory correction logs | H3: Verify trajectory tolerance | I3: Medium | J3: Launch Complete | K3: 6 years | L3: Periodic health monitoring
A4: Europa Arrival | B4: Europa Orbit Insertion | C4: Achieve Stable Europa Orbit | D4: Autonomous | E4: Orbital state measurements | F4: Orbital telemetry | G4: Orbit determination solution | H4: Verify stable orbit | I4: High | J4: Cruise Complete | K4: 1 day | L4: Critical maneuver
A5: Orbit Day 1-15 | B5: Terrain Mapping | C5: Generate Landing Candidates | D5: Autonomous | E5: Orbital imagery, radar scans | F5: Hazard maps | G5: Global terrain maps | H5: Verify terrain coverage | I5: Medium | J5: Orbit Insertion complete | K5: 15 das | L5: Orbital Agent 1
A6: Orbit Day 15-30 | B6: Communications Relay & Localization Support | C6: Validate Landing Regions | D6: Autonomous | E6: Orbital navigation data | F6: Localization updates | G6: Navigation support database | H6: Verify location accuracy | I6: Medium | J6: Terrain Mapping complete | K6: 15 days | L6: Orbital Agent 2
A7: Surface Day 0 | B7: Rover Landing | C7: Safe Landing | D7: Autonomous | E7: Landing guidance sensors | F7: Landing telemetry | G7: Landing performance report | H7: Verify touchdown location | I7: High | J7: Landing Site selected | K7: 4 hrs | L7: Highest risk phase
A8: Surface Day 1 | B8: Payload Initialization | C8: Activate Science Payloads | D8: Autonomous | E8: Startup commands | F8: Instrument health telemetry | G8: Payload status report | H8: Verify payload functionality | I8: Medium | J8: Landing Complete | K8: 6 hrs | L8: New 2.4 activity
A9: Surface Day 1-2 | B9: Radar Calibration | C9: Calibrate Radar Sonar | D9: Autonomous | E9: Calibration routines | F9: Calibration measurements | G9: Calibration dataset | H9: Verify measurement accuracy | I9: Low | J9: Payload initialization complete | K9: 1 day | L9: New 2.4 activity
A10: Surface Day 2-5 | B10: Traverse Planning | C10: Generate Survey Route | D10: Autonomous | E10: Terrain maps, hazard maps | F10: Planned route | G10: Navigation plan | H10: Verify route safety | I10: Medium | J10: Calibration complete | K10: 3 days | L10: New 2.4 activity
A11: Surface Day 5-20 | B11: Autonomous Navigation | C11: Transverse Survey Area | D11: Autonomous | E11: Terrain maps, localization estimates | F11: Position updates | G11: Traverse logs | H11: Verify localization accuracy | I11: Medium | J11: Route planning complete | K11: 15 days | L11: Expanded from 2.3
A12: Surface Day 5-20 | B12: Radar Data Collected | C12: Acquire Subsurface Measurements | D12: Autonomous | E12: Radar returns | F12: Ice thickness estimates | G12: Radar profiles | H12: Verify coverage requirements | I12: Medium | J12: Navigation Active | K12: 15 days | L12: Expanded from 2.3
... A16: Surface Day 29-30 | B16: Data transmission & End Mission | C16: Downlink Archive And Close Mission | D16: Semi-Autonomous | E16: Science archive | F16: Archive transmission | G16: Final mission report | H16: Verify archive receipt | I16: Low | J16: Site selection complete | K16: 1 day | L16: Mission end

Sheet minute-by-minute breakdown
A1: Sol | B1: Mission Elapsed Time (min) | C1: Mode: Sub-Activity | E1: Minute By Minute Ranges
A2: 0 | B2: 0-15 | C2: Europa Descent And Landing | E2: Mode | F2: Duration (min)
A3: 0 | B3: 16-30 | C3: Verify Successful Landing | E3: Initialization
A4: 0 | B4: 31-120 | C4: Rover Commisioning And Health Checks | E4: Europa Descent And Landing | F4: 15
A5: 0 | B5: 121-180 | C5: Orbital Communications Verification | E5: Verify Successful Landing | F5: 15
A6: 0 | B6: 181-300 | C6: Localization Initialization | E6: Rover Commisioning And Health Checks | F6: 90
A7: 0 | B7: 301-420 | C7: Radar Payload Initialization | E7: Orbital Communications Verification | F7: 60
A8: 0 | B8: 421-540 | C8: Radar Calibration And Validation | E8: Localization Initialization | F8: 120
A9: 0 | B9: 541-720 | C9: Initial Site Characterization | E9: Radar Payload Initialization | F9: 120
A10: 0 | B10: 721-1440 | C10: Night Low-Power Thermal Managment | E10: Radar Calibration And Validation | F10: 120
A11: 1 | B11: 1441-1500 | C11: Autonomous Traverse Plan | E11: Initial Site Characterization | F11: 180
A12: 1 | B12: 1501-1560 | C12: Orbital Terrain Mapping Update | E12: Night Low-Power Thermal Managment | F12: 720
A13: 1 | B13: 1561-1800 | C13: Surface Survery Block A | E13: Activation State
A14: 1 | B14: 1801-1860 | C14: Localization Verificaion | E14: Autonomous Traverse Plan | F14: 60
A15: 1 | B15: 1861-2100 | C15: Radar Data Collection Block A | E15: Orbital Terrain Mapping Update | F15: 60
A16: 1 | B16: 2101-2190 | C16: Comminucation Relay Pass | E16: Surface Survery Block A | F16: 240
A17: 1 | B17: 2191-2400 | C17: Surface Survey Block B | E17: Localization Verificaion | F17: 60
A18: 1 | B18: 2401-2880 | C18: Night Low-Power Thermal Managment | E18: Radar Data Collection Block A | F18: 240
A19: 2 | B19: 2881-2940 | C19: Systems Warm-Up | E19: Comminucation Relay Pass | F19: 90
A20: 2 | B20: 2941-3240 | C20: Radar Data Collection Block B | E20: Surface Survey Block B | F20: 210
A21: 2 | B21: 3241-3300 | C21: Autonomous Hazard Assertion Plan | E21: Systems Warm-Up | F21: 60
A22: 2 | B22: 3301-3540 | C22: Surface Survey Block C | E22: Radar Data Collection Block B | F22: 300
A23: 2 | B23: 3541-3630 | C23: Comminucation Relay Pass | E23: Autonomous Hazard Assertion Plan | F23: 60
A24: 2 | B24: 3631-3900 | C24: Subsurface Ice Map Generation | E24: Surface Survey Block C | F24: 240
A25: 2 | B25: 3900-4320 | C25: Night Low-Power Thermal Managment | E25: Comminucation Relay Pass | F25: 90
A26: STEADY STATE OPERATIONS | E26: Subsurface Ice Map Generation | F26: 270
A27: 46106 | B27: Repeating Daily Cycle | C27: Traverse Planning | E27: Steady State
A28: 46106 | B28: Repeating Daily Cycle | C28: Survey Operations | E28: Traverse Planning | F28: 60
A29: 46106 | B29: Repeating Daily Cycle | C29: Radar Data Collection | E29: Survey Operations | F29: 240
A30: 46106 | B30: Repeating Daily Cycle | C30: Communications Relay Pass | E30: Radar Data Collection | F30: 300
A31: 46106 | B31: Repeating Daily Cycle | C31: Subsurface Ice Map Updates | E31: Communications Relay Pass | F31: 90
A32: 46106 | B32: Repeating Daily Cycle | C32: Night Low-Power Thermal Managment | E32: Subsurface Ice Map Updates | F32: 270
A33: SITE SELECTION PHASE | E33: Autonomous Consensus Validation | F33: 120
A34: 26 | B34: 36001-36360 | C34: Candidate Site Ranking | E34: Candidate Site Ranking | F34: 120
A35: 26 | B35: 36361-36720 | C35: Autonomous Consensus Validation | E35: Night Low-Power Thermal Managment | F35: 240
A36: 26 | B36: 36721-37440 | C36: Night Low-Power Thermal Managment | E36: SITE SELECTION PHASE
A37: 27 | B37: 37441-37800 | C37: Candidate Site Ranking | E37: Candidate Site Ranking | F37: 360
A38: 27 | B38: 37801-38160 | C38: Autonomous Consensus Validation | E38: Autonomous Consensus Validation | F38: 360
A39: 27 | B39: 38161-38880 | C39: Night Low-Power Thermal Managment | E39: Final Site Assesment | F39: 360
A40: 28 | B40: 38881-39240 | C40: Final Site Assesment | E40: Cryobot Site Selection | F40: 360
...
